File: sub_vi-s/Equipment/PPMS/ConfigModel6000/p14log_model6000_vom_p9_12192019.dat
[Header]
; Copyright 1997-99, Quantum Design, Inc. All rights reserved.
TITLE, PPMS Log Data File
FILEOPENTIME,30354124.92,12/19/2019,4:10 PM
BYAPP, LogData, 1.1, 2.0
INFO, APPNAME, PPMS MultiVu Application, 1.5.11
FIELDGROUP, Standard,2,3,4,5,6,7,8,9,10,11,12,13,14,15,16,17,18,19,20,21,22,23,24,25,26,27,28,29,30,31,32
FIELDGROUP, Diagnostic,2,32,33,34,35,36,37,38,39,40,41,42,43,44,45,46,47,48,49,50,51,52,53,54
FIELDGROUP, User,2,64,65,66,67,68,69,70,71,72,73,74,75,76,77,78,79,80,81,82,83,84,85,86,87,88,89,90,91,92,93
FIELDGROUP, MAP User,2,96,97,98,99,100,101,102,103,104,105,106,107,108,109,110,111,112,113,114,115,116,117,118,119,120,121,122,123,124,125
STARTUPGROUP, All
STARTUPAXIS, X, 2, LINEAR, AUTO
STARTUPAXIS, Y1, 4, LINEAR, AUTO
TIMEMODE, MINUTES, RELATIVE
PLOT_APPEARANCE, ALL, HORZ_GRID_ON, VERT_GRID_ON, MARKERS_AND_LINES, ALL_LINES
RECORDS, ALL_RECORDS
DATATYPE, TIME, 2
DATATYPE, COMMENT, 1
[Data]
Comment,Time Stamp (sec),Status (code),Temperature (K),Magnetic Field (Oe),Sample Position (deg),Bridge 1 Resistance (ohms),Bridge 1 Excitation (uA),Bridge 2 Resistance (ohms),Bridge 2 Excitation (uA),Bridge 3 Resistance (ohms),Bridge 3 Excitation (uA),Bridge 4 Resistance (ohms),Bridge 4 Excitation (uA),Signal 1 Vin (V),Signal 2 Vin (V),Digital Inputs (code),Drive 1 Iout (mA),Drive 1 Ipower (watts),Drive 2 Iout (mA),Drive 2 Ipower (watts),Pressure (),Map 20 (),Map 21 (),Map 22 (),H_Rotator (K),Map 24 (),Map 25 (),Map 26 (),Map 27 (),Map 28 (),Map 29 (),System Status (code),Setpoint (K),Magnet (Oe),Valve Position (deg),CIG/Cernox (K),CIG Excit (uA),Plat Therm (K),Plat Excit (uA),Neck Therm (K),Neck Excit (uA),Spare Therm (K),Spare Excit (uA),Flow Rate (l/min),Annulus Vacuum (V),Impedance (mode),Block Htr Cur (mA),Block Htr Pwr (W),Neck Htr Cur (mA),Neck Htr Pwr (W),Annulus Pres (Torr),System Pres (Torr),Tableless Map53 (),Tableless Map54 (),Redirected 55 (),Redirected 56 (),Redirected 57 (),Redirected 58 (),Redirected 59 (),FlowSensor_V,Redirected 61 (),Seq Stat (),Sys Temp (),He Level (),Map 67 (),Map 68 (),Map 69 (),PSU Field (Oe),Hi res (A) read,Mag (V) read,Mag adj/sc(I)set,Sw heater state,DAC <I> (cnts),Therm V,KRPMs,Pump temp (C),pump power (W),High Vacuum mode,Flapper state,Regen htr flag,iso flag,BlockHeater(Ohm),NeckHeater(Ohm),Map 86 (),Map 87 (),Map 88 (),Map 89 (),Map 90 (),Map 91 (),Map 92 (),Map 93 (),MAP 1,MAP 2,MAP 3,MAP 4,MAP 5,MAP 6,MAP 7,MAP 8,MAP 9,MAP 10,MAP 11,MAP 12,MAP 13,MAP 14,MAP 15,MAP 16,MAP 17,MAP 18,MAP 19,MAP 20,MAP 21,MAP 22,MAP 23,MAP 24,MAP 25,MAP 26,MAP 27,MAP 28,MAP 29,MAP 30
,30354125.00,4870,265.4448,120.000,90.0143967,,,,,,,,,0.0000,-0.0049,256,0.00,0.00,0.00,0.00,4.2659898,,,,,,,,,,,4870,262.892,120.000,90.0,265.4447937,105.032,265.5506592,896.434,267.6276855,109.917,,,3.742862e-2,0.449438,0.5,0.00,0.00,0.00,0.00,811.8547363,-4.132275,,,,,,,,-3.9081585e-2,,1.0,265.4448,100.1,,,,120.0000,120.0000,-5.0000,0.00,0,0,2.5000,,,,0,0.00,0,0.00,35.63,23.53,,,,,,,,
,30354220.17,4870,265.2758,120.000,90.0143967,,,,,,,,,-0.0049,-0.0147,256,0.00,0.00,0.00,0.00,4.3237367,,,,,,,,,,,4870,262.713,120.000,90.0,265.2757568,105.032,265.3744507,896.434,267.4709167,109.917,,,4.170317e-2,0.439668,0.5,0.00,0.00,0.00,0.00,811.8547363,-3.743996,,,,,,,,-3.4196384e-2,,1.0,265.2758,100.1,,,,120.0000,120.0000,-5.0000,0.00,0,0,2.5000,,,,0,0.00,0,0.00,35.63,23.53,,,,,,,,
,30354315.14,4870,265.1241,120.000,90.0143967,,,,,,,,,-0.0098,-0.0147,256,0.00,0.00,0.00,0.00,4.2659898,,,,,,,,,,,4870,262.533,120.000,90.0,265.1241150,105.032,265.2117920,896.434,267.3116455,109.673,,,4.170317e-2,0.444553,0.5,0.00,0.00,0.00,0.00,810.6171875,-4.520555,,,,,,,,-3.4196384e-2,,1.0,265.0962,100.1,,,,120.0000,120.0000,-5.0000,0.00,0,0,2.5000,,,,0,0.00,0,0.00,35.63,23.53,,,,,,,,
,30354410.05,4870,264.9324,120.000,90.0143967,,,,,,,,,-0.0049,-0.0049,256,0.00,0.00,0.00,0.00,4.3822122,,,,,,,,,,,4870,262.353,120.000,90.0,264.9197083,104.787,265.0262146,896.434,267.1280212,109.673,,,2.887953e-2,0.434783,0.5,0.00,0.00,0.00,0.00,811.4421997,-3.743996,,,,,,,,-4.8851978e-2,,1.0,264.9197,100.1,,,,120.0000,120.0000,-5.0000,0.00,0,0,2.5000,,,,0,0.00,0,0.00,35.63,23.53,,,,,,,,
,30354505.08,4870,264.7405,120.000,90.0143967,,,,,,,,,-0.0098,-0.0147,0,0.00,0.00,0.00,0.00,4.2659898,,,,,,,,,,,4870,262.233,120.000,90.0,264.7404785,104.787,264.8599548,950.171,266.9599609,109.673,,,3.742862e-2,0.444553,0.0,0.00,0.00,0.00,0.00,809.7921143,-4.132275,,,,,,,,-3.9081585e-2,,1.0,264.7506,100.1,,,,120.0000,120.0000,-5.0000,0.00,0,0,2.5000,,,,0,0.00,0,0.00,35.63,23.53,,,,,,,,
,30354600.22,4870,264.5870,120.000,90.0143967,,,,,,,,,-0.0147,-0.0049,0,0.00,0.00,0.00,0.00,4.1526480,,,,,,,,,,,4870,262.053,120.000,90.0,264.5870056,104.787,264.6884155,950.171,266.8290100,109.428,,,2.887953e-2,0.434783,0.0,0.00,0.00,0.00,0.00,810.2045898,-4.520555,,,,,,,,-4.8851978e-2,,1.0,264.5870,100.1,,,,120.0000,120.0000,-5.0000,0.00,0,0,2.5000,,,,0,0.00,0,0.00,35.63,23.53,,,,,,,,
,30354695.14,4870,264.4054,120.000,90.0143967,,,,,,,,,-0.0098,-0.0049,0,0.00,0.00,0.00,0.00,4.3237367,,,,,,,,,,,4870,261.869,120.000,90.0,264.4053955,104.787,264.5228882,950.171,266.6602783,109.428,,,3.742862e-2,0.439668,0.0,0.00,0.00,0.00,0.00,809.7921143,-3.743996,,,,,,,,-3.9081585e-2,,1.0,264.4054,100.1,,,,120.0000,120.0000,-5.0000,0.00,0,0,2.5000,,,,0,0.00,0,0.00,35.63,23.53,,,,,,,,
,30354790.02,4870,264.2371,120.000,90.0143967,,,,,,,,,0.0000,-0.0147,0,0.00,0.00,0.00,0.00,4.2659898,,,,,,,,,,,4870,261.690,120.000,90.0,264.2371216,104.543,264.3575745,950.171,266.4744263,109.428,,,2.887953e-2,0.444553,0.0,0.00,0.00,0.00,0.00,810.2045898,-3.743996,,,,,,,,-4.8851978e-2,,1.0,264.2346,100.1,,,,120.0000,120.0000,-5.0000,0.00,0,0,2.5000,,,,0,0.00,0,0.00,35.63,23.53,,,,,,,,
,30354885.02,4870,264.0612,120.000,90.0143967,,,,,,,,,0.0000,-0.0049,0,0.00,0.00,0.00,0.00,4.2089629,,,,,,,,,,,4870,261.510,120.000,90.0,264.0612488,104.543,264.1862488,950.171,266.3157043,109.428,,,3.742862e-2,0.444553,0.0,0.00,0.00,0.00,0.00,809.7921143,-4.520555,,,,,,,,-3.9081585e-2,,1.0,264.0714,100.1,,,,120.0000,120.0000,-5.0000,0.00,0,0,2.5000,,,,0,0.00,0,0.00,35.63,23.53,,,,,,,,
,30354980.05,4870,263.8946,120.000,90.0143967,,,,,,,,,-0.0098,-0.0147,0,0.00,0.00,0.00,0.00,4.2659898,,,,,,,,,,,4870,261.330,120.000,90.0,263.8970947,104.543,264.0188904,950.171,266.1579285,109.184,,,2.887953e-2,0.449438,0.0,0.00,0.00,0.00,0.00,809.7921143,-3.743996,,,,,,,,-4.8851978e-2,,1.0,263.8971,100.1,,,,120.0000,120.0000,-5.0000,0.00,0,0,2.5000,,,,0,0.00,0,0.00,35.63,23.53,,,,,,,,
,30355075.05,4870,263.7527,120.000,90.0143967,,,,,,,,,-0.0049,-0.0049,0,0.00,0.00,0.00,0.00,4.2089629,,,,,,,,,,,4870,261.150,120.000,90.0,263.7552490,104.543,263.8448792,950.171,266.0048523,109.184,,,2.887953e-2,0.444553,0.0,0.00,0.00,0.00,0.00,809.3795776,-3.355717,,,,,,,,-4.8851978e-2,,1.0,263.7552,100.1,,,,120.0000,120.0000,-5.0000,0.00,0,0,2.5000,,,,0,0.00,0,0.00,35.63,23.53,,,,,,,,
,30355170.13,4870,263.5790,120.000,90.0143967,,,,,,,,,0.0000,-0.0147,0,0.00,0.00,0.00,0.00,4.3237367,,,,,,,,,,,4870,261.061,120.000,90.0,263.5789795,104.299,263.6919250,950.171,265.8583984,109.184,,,2.887953e-2,0.444553,0.0,0.00,0.00,0.00,0.00,809.7921143,-4.520555,,,,,,,,-4.8851978e-2,,1.0,263.5790,100.1,,,,120.0000,120.0000,-5.0000,0.00,0,0,2.5000,,,,0,0.00,0,0.00,35.63,23.53,,,,,,,,
,30355265.05,4870,263.4275,120.000,90.0143967,,,,,,,,,-0.0049,-0.0147,0,0.00,0.00,0.00,0.00,4.3822122,,,,,,,,,,,4870,260.881,120.000,90.0,263.4274597,104.299,263.5252686,950.171,265.6877747,109.184,,,4.170317e-2,0.434783,0.0,0.00,0.00,0.00,0.00,811.0296631,-3.743996,,,,,,,,-3.4196384e-2,,1.0,263.4275,63.8,,,,120.0000,120.0000,-5.0000,0.00,0,0,2.5000,,,,0,0.00,0,0.00,35.63,23.53,,,,,,,,
,30355360.11,4870,263.2612,120.000,90.0143967,,,,,,,,,-0.0147,-0.0147,0,0.00,0.00,0.00,0.00,4.3822122,,,,,,,,,,,4870,260.701,120.000,90.0,263.2611694,104.299,263.3666992,950.171,265.5403748,108.940,,,3.742862e-2,0.449438,0.0,0.00,0.00,0.00,0.00,809.3795776,-4.520555,,,,,,,,-3.9081585e-2,,1.0,263.2612,63.8,,,,120.0000,120.0000,-5.0000,0.00,0,0,2.5000,,,,0,0.00,0,0.00,35.63,23.53,,,,,,,,
,30355455.16,4870,263.0130,120.000,90.0143967,,,,,,,,,-0.0147,-0.0147,0,0.00,0.00,0.00,0.00,4.3237367,,,,,,,,,,,4870,260.432,120.000,90.0,263.0130310,104.055,263.1503906,950.171,265.3579407,108.940,,,3.652786,3.561309,0.0,0.00,0.00,0.00,0.00,771.8395386,-3.355717,,,,,,,,7.1030779,,1.0,263.0130,63.8,,,,120.0000,120.0000,-5.0000,0.00,0,0,2.5000,,,,0,0.00,0,0.00,35.63,23.53,,,,,,,,
,30355550.05,4870,252.6196,120.000,90.0143967,,,,,,,,,-0.0098,-0.0147,0,0.00,0.00,0.00,0.00,4.2089629,,,,,,,,,,,4870,250.037,120.000,90.0,252.6195679,100.147,253.2428894,950.171,264.4958496,108.696,,,3.706455,3.551539,0.0,0.00,0.00,0.00,0.00,771.8395386,-4.132275,,,,,,,,7.2007818,,1.0,252.5714,63.8,,,,120.0000,120.0000,-5.0000,0.00,0,0,2.5000,,,,0,0.00,0,0.00,35.63,23.53,,,,,,,,
,30355645.06,4870,237.8019,120.000,90.0143967,,,,,,,,,-0.0147,-0.0147,0,0.00,0.00,0.00,0.00,4.0970364,,,,,,,,,,,4870,235.264,120.000,90.0,237.8018799,94.040,238.4361267,999.023,260.0692749,106.742,,,3.744023,3.561309,0.0,0.00,0.00,0.00,0.00,771.4270020,-4.132275,,,,,,,,7.2691746,,1.0,237.7364,63.8,,,,120.0000,120.0000,-5.0000,0.00,0,0,2.5000,,,,0,0.00,0,0.00,35.63,23.53,,,,,,,,
,30355739.94,4870,221.9267,120.000,90.0143967,,,,,,,,,-0.0049,-0.0147,0,0.00,0.00,0.00,0.00,3.9343431,,,,,,,,,,,4870,219.412,120.000,90.0,221.8546600,87.689,222.4475098,999.023,251.9357910,103.322,,,3.765490,3.571080,0.0,0.00,0.00,0.00,0.00,769.3643799,-3.743996,,,,,,,,7.3082561,,1.0,221.8547,63.8,,,,120.0000,120.0000,-5.0000,0.00,0,0,2.5000,,,,0,0.00,0,0.00,35.63,23.53,,,,,,,,
,30355835.16,4870,205.6587,120.000,90.0143967,,,,,,,,,-0.0098,-0.0147,0,0.00,0.00,0.00,0.00,3.9343431,,,,,,,,,,,4870,203.131,120.000,90.0,205.6587219,81.339,206.2230530,999.023,241.0182037,98.681,,,3.776223,3.585735,0.0,0.00,0.00,0.00,0.00,768.9518433,-4.520555,,,,,,,,7.3277969,,1.0,205.6587,63.8,,,,120.0000,120.0000,-5.0000,0.00,0,0,2.5000,,,,0,0.00,0,0.00,35.63,23.53,,,,,,,,
,30355930.09,4870,189.8022,120.000,90.0143967,,,,,,,,,-0.0049,-0.0049,0,0.00,0.00,0.00,0.00,3.8292661,,,,,,,,,,,4870,187.358,120.000,90.0,189.8021545,74.988,190.2560730,999.023,228.1820068,93.307,,,3.797691,3.585735,0.0,0.00,0.00,0.00,0.00,768.5393677,-3.743996,,,,,,,,7.3668785,,1.0,189.8022,63.8,,,,120.0000,120.0000,-5.0000,0.00,0,0,2.5000,,,,0,0.00,0,0.00,35.63,23.53,,,,,,,,
,30356025.06,4870,174.6512,120.000,90.0143967,,,,,,,,,-0.0098,-0.0147,0,0.00,0.00,0.00,0.00,3.7777154,,,,,,,,,,,4870,172.150,120.000,90.0,174.6512146,68.881,175.0441132,999.023,213.9678802,87.445,,,3.813791,3.590621,0.0,0.00,0.00,0.00,0.00,768.5393677,-3.355717,,,,,,,,7.3961897,,1.0,174.6512,63.8,,,,120.0000,120.0000,-5.0000,0.00,0,0,2.5000,,,,0,0.00,0,0.00,35.63,23.53,,,,,,,,
,30356119.97,4870,160.5041,120.000,90.0143967,,,,,,,,,0.0000,-0.0147,0,0.00,0.00,0.00,0.00,3.6269238,,,,,,,,,,,4870,157.998,120.000,90.0,160.5041199,63.263,160.8444214,999.023,199.5272064,81.339,,,3.816475,3.590621,0.0,0.00,0.00,0.00,0.00,768.1267700,-3.355717,,,,,,,,7.4010749,,1.0,160.5041,63.8,,,,120.0000,120.0000,-5.0000,0.00,0,0,2.5000,,,,0,0.00,0,0.00,35.63,23.53,,,,,,,,
,30356215.17,4870,147.2285,120.000,90.0143967,,,,,,,,,0.0000,-0.0049,0,0.00,0.00,0.00,0.00,3.4817646,,,,,,,,,,,4870,144.690,120.000,90.0,147.2285309,58.134,147.5244293,999.023,184.9401398,75.232,,,3.829892,3.590621,0.0,0.00,0.00,0.00,0.00,767.7142944,-4.132275,,,,,,,,7.4255009,,1.0,147.1835,63.8,,,,120.0000,120.0000,-5.0000,0.00,0,0,2.5000,,,,0,0.00,0,0.00,35.63,23.53,,,,,,,,
,30356310.08,4870,134.6814,120.000,90.0143967,,,,,,,,,-0.0098,-0.0147,0,0.00,0.00,0.00,0.00,3.3420408,,,,,,,,,,,4870,132.096,120.000,90.0,134.6814270,53.004,134.9108429,999.023,170.5151825,69.126,,,3.835259,3.595506,0.0,0.00,0.00,0.00,0.00,768.1267700,-4.132275,,,,,,,,7.4352713,,1.0,134.6814,63.8,,,,120.0000,120.0000,-5.0000,0.00,0,0,2.5000,,,,0,0.00,0,0.00,35.63,23.53,,,,,,,,
,30356405.11,4870,122.7362,120.000,90.0143967,,,,,,,,,-0.0049,-0.0147,0,0.00,0.00,0.00,0.00,3.3420408,,,,,,,,,,,4870,120.002,120.000,90.0,122.7362061,48.559,122.8894958,999.023,156.2713318,63.263,,,3.840626,3.585735,0.0,0.00,0.00,0.00,0.00,767.7142944,-3.355717,,,,,,,,7.4450417,,1.0,122.7362,63.8,,,,120.0000,120.0000,-5.0000,0.00,0,0,2.5000,,,,0,0.00,0,0.00,35.63,23.53,,,,,,,,
,30356500.02,4870,111.3401,120.000,90.0143967,,,,,,,,,-0.0049,-0.0147,0,0.00,0.00,0.00,0.00,3.2075617,,,,,,,,,,,4870,108.733,120.000,90.0,111.3401489,44.138,111.4596634,999.023,142.6781464,57.645,,,3.854043,3.590621,0.0,0.00,0.00,0.00,0.00,766.4766846,-4.520555,,,,,,,,7.4694676,,1.0,111.3401,63.8,,,,120.0000,120.0000,-5.0000,0.00,0,0,2.5000,,,,0,0.00,0,0.00,35.63,23.53,,,,,,,,
,30356595.14,4870,100.3127,120.000,90.0143967,,,,,,,,,0.0000,-0.0147,0,0.00,0.00,0.00,0.00,3.0781438,,,,,,,,,,,4870,97.740,120.000,90.0,100.3126526,39.912,100.3834076,999.023,129.3216553,52.027,,,3.854043,3.595506,0.0,0.00,0.00,0.00,0.00,767.3016968,-4.520555,,,,,,,,7.4694676,,1.0,100.3127,63.6,,,,120.0000,120.0000,-5.0000,0.00,0,0,2.5000,,,,0,0.00,0,0.00,35.63,23.53,,,,,,,,
,30356690.11,4870,89.6227,120.000,90.0143967,,,,,,,,,-0.0098,-0.0147,0,0.00,0.00,0.00,0.00,2.7545085,,,,,,,,,,,4870,87.080,120.000,90.0,89.6227493,35.833,89.6985779,999.023,116.0681458,46.825,,,3.856726,3.580850,0.0,0.00,0.00,0.00,0.00,767.3016968,-3.355717,,,,,,,,7.4743528,,1.0,89.6227,63.6,,,,120.0000,120.0000,-5.0000,0.00,0,0,2.5000,,,,0,0.00,0,0.00,35.63,23.53,,,,,,,,
,30356785.11,4870,79.2610,120.000,90.0143967,,,,,,,,,-0.0049,-0.0147,0,0.00,0.00,0.00,0.00,2.4630363,,,,,,,,,,,4870,76.701,120.000,90.0,79.2609558,31.876,79.3036118,999.023,102.9161835,41.549,,,3.851359,3.590621,0.0,0.00,0.00,0.00,0.00,766.8892212,-3.743996,,,,,,,,7.4645824,,1.0,79.2610,63.6,,,,120.0000,120.0000,-5.0000,0.00,0,0,2.5000,,,,0,0.00,0,0.00,35.63,23.53,,,,,,,,
,30356880.16,4870,68.8297,120.000,90.0143967,,,,,,,,,-0.0147,-0.0049,0,0.00,0.00,0.00,0.00,2.1406133,,,,,,,,,,,4870,66.213,120.000,90.0,68.8296509,27.919,68.8455963,999.023,89.7764053,36.297,,,3.864776,3.590621,0.0,0.00,0.00,0.00,0.00,766.0641479,-4.520555,,,,,,,,7.4890084,,1.0,68.8297,63.6,,,,120.0000,120.0000,-5.0000,0.00,0,0,2.5000,,,,0,0.00,0,0.00,35.63,23.53,,,,,,,,
,30356975.08,4870,58.1759,120.000,90.0143967,,,,,,,,,-0.0147,-0.0049,0,0.00,0.00,0.00,0.00,1.7577385,,,,,,,,,,,4870,55.631,120.000,90.0,58.1758842,23.864,58.1785240,999.023,76.3382034,30.972,,,3.870143,3.580850,0.0,0.00,0.00,0.00,0.00,766.4766846,-2.967438,,,,,,,,7.4987788,,1.0,58.1347,63.6,,,,120.0000,120.0000,-5.0000,0.00,0,0,2.5000,,,,0,0.00,0,0.00,35.63,23.53,,,,,,,,
,30357070.02,4870,46.4449,120.000,90.0143967,,,,,,,,,-0.0098,-0.0147,0,0.00,0.00,0.00,0.00,1.3581861,,,,,,,,,,,4870,44.111,120.000,90.0,46.4449348,19.394,46.4210815,999.023,62.1077614,25.379,,,3.875510,3.595506,0.0,0.00,0.00,0.00,0.00,766.8892212,-4.520555,,,,,,,,7.5085492,,1.0,46.4449,63.6,,,,120.0000,120.0000,-5.0000,0.00,0,0,2.5000,,,,0,0.00,0,0.00,35.63,23.53,,,,,,,,
,30357165.17,4870,31.7333,120.000,90.0143967,,,,,,,,,-0.0098,-0.0049,0,0.00,0.00,0.00,0.00,0.9867581,,,,,,,,,,,4870,29.916,120.000,90.0,31.7333298,13.703,31.6967640,999.023,46.0085716,19.003,,,3.888927,3.600391,0.0,0.00,0.00,0.00,0.00,766.8892212,-4.520555,,,,,,,,7.5329752,,1.0,31.7333,63.6,,,,120.0000,120.0000,-5.0000,0.00,0,0,2.5000,,,,0,0.00,0,0.00,35.63,23.53,,,,,,,,
,30357259.98,4871,9.5082,120.000,90.0143967,,,,,,,,,-0.0098,-0.0049,0,0.00,0.00,0.00,0.00,0.5222437,,,,,,,,,,,4871,8.999,120.000,90.0,9.5082102,4.443,14.6096516,999.023,24.8253212,10.650,,,3.878193,3.595506,0.0,95.48,0.18378,0.00,0.00,766.4766846,-3.355717,,,,,,,,7.5134344,,1.0,9.5082,63.6,,,,120.0000,120.0000,-5.0000,0.00,0,0,2.5000,,,,0,0.00,0,0.00,20.26,23.53,,,,,,,,
,30357355.13,4871,9.4833,120.000,90.0143967,,,,,,,,,-0.0049,-0.0147,0,0.00,0.00,0.00,0.00,0.4222528,,,,,,,,,,,4871,8.999,120.000,90.0,9.4832621,4.443,14.6034498,999.023,14.7363729,6.571,,,3.899661,3.600391,0.0,142.61,0.41453,0.00,0.00,765.6516113,-3.743996,,,,,,,,7.5525160,,1.0,9.4833,63.6,,,,120.0000,120.0000,-5.0000,0.00,0,0,2.5000,,,,0,0.00,0,0.00,20.38,23.53,,,,,,,,
,30357450.16,4871,9.2710,120.000,90.0143967,,,,,,,,,0.0000,-0.0147,0,0.00,0.00,0.00,0.00,0.3591578,,,,,,,,,,,4871,8.801,120.000,90.0,9.2710085,4.436,14.5696993,999.023,10.8261337,4.846,,,3.902344,3.600391,0.0,148.23,0.44896,0.00,0.00,766.0641479,-3.743996,,,,,,,,7.5574012,,1.0,9.2710,63.6,,,,120.0000,120.0000,-5.0000,0.00,0,0,2.5000,,,,0,0.00,0,0.00,20.43,23.53,,,,,,,,
,30357545.17,4871,9.0262,120.000,90.0143967,,,,,,,,,-0.0049,-0.0098,0,0.00,0.00,0.00,0.00,0.3133280,,,,,,,,,,,4871,8.535,120.000,90.0,9.0262098,4.316,14.5349798,999.023,9.3782187,4.201,,,3.905027,3.595506,0.0,148.23,0.44896,0.00,0.00,765.6516113,-3.743996,,,,,,,,7.5622864,,1.0,9.0262,63.6,,,,120.0000,120.0000,-5.0000,0.00,0,0,2.5000,,,,0,0.00,0,0.00,20.43,23.53,,,,,,,,
,30357640.02,4871,8.7050,120.000,90.0143967,,,,,,,,,0.0000,-0.0098,0,0.00,0.00,0.00,0.00,0.2541952,,,,,,,,,,,4871,8.262,120.000,90.0,8.7049980,4.160,14.4935102,999.023,8.7536793,3.911,,,3.910394,3.590621,0.0,145.79,0.43622,0.00,0.00,765.2391357,-4.132275,,,,,,,,7.5720568,,1.0,8.7050,63.6,,,,120.0000,120.0000,-5.0000,0.00,0,0,2.5000,,,,0,0.00,0,0.00,20.52,23.53,,,,,,,,
,30357735.03,4871,8.4940,120.000,90.0143967,,,,,,,,,-0.0049,-0.0098,0,0.00,0.00,0.00,0.00,0.2177116,,,,,,,,,,,4871,8.032,120.000,90.0,8.4939547,4.052,14.4684620,999.023,8.4601908,3.769,,,3.907711,3.595506,0.0,144.32,0.42479,0.00,0.00,764.8265381,-3.355717,,,,,,,,7.5671716,,1.0,8.4940,63.6,,,,120.0000,120.0000,-5.0000,0.00,0,0,2.5000,,,,0,0.00,0,0.00,20.39,23.53,,,,,,,,
,30357829.95,4871,8.2942,120.000,90.0143967,,,,,,,,,-0.0098,-0.0147,0,0.00,0.00,0.00,0.00,0.1863489,,,,,,,,,,,4871,7.858,120.000,90.0,8.2941551,3.955,14.4464521,999.023,8.2299585,3.659,,,3.910394,3.590621,0.0,142.61,0.41627,0.00,0.00,764.8265381,-4.132275,,,,,,,,7.5720568,,1.0,8.2958,63.6,,,,120.0000,120.0000,-5.0000,0.00,0,0,2.5000,,,,0,0.00,0,0.00,20.47,23.53,,,,,,,,
,30357925.00,4871,8.1131,120.000,90.0143967,,,,,,,,,-0.0098,-0.0098,0,0.00,0.00,0.00,0.00,0.1687238,,,,,,,,,,,4871,7.689,120.000,90.0,8.1131296,3.864,14.4279203,999.023,8.0307722,3.561,,,3.886244,3.590621,0.0,139.93,0.39818,0.00,0.00,765.2391357,-3.743996,,,,,,,,7.5280900,,1.0,8.1131,63.6,,,,120.0000,120.0000,-5.0000,0.00,0,0,2.5000,,,,0,0.00,0,0.00,20.34,23.53,,,,,,,,
,30358019.94,4871,7.9486,120.000,90.0143967,,,,,,,,,-0.0147,-0.0049,0,0.00,0.00,0.00,0.00,0.1548232,,,,,,,,,,,4871,7.523,120.000,90.0,7.9485712,3.779,14.4119997,999.023,7.8512030,3.471,,,3.859409,3.585735,0.0,137.24,0.38215,0.00,0.00,764.8265381,-4.132275,,,,,,,,7.4792380,,1.0,7.9486,63.6,,,,120.0000,120.0000,-5.0000,0.00,0,0,2.5000,,,,0,0.00,0,0.00,20.29,23.53,,,,,,,,
,30358115.14,4871,7.8014,120.000,90.0143967,,,,,,,,,0.0000,-0.0049,0,0.00,0.00,0.00,0.00,0.1377735,,,,,,,,,,,4871,7.398,120.000,90.0,7.8014164,3.703,14.3981085,999.023,7.6919241,3.393,,,3.816475,3.580850,0.0,133.82,0.36610,0.00,0.00,765.2391357,-3.355717,,,,,,,,7.4010749,,1.0,7.8002,63.6,,,,120.0000,120.0000,-5.0000,0.00,0,0,2.5000,,,,0,0.00,0,0.00,20.26,23.53,,,,,,,,
,30358210.08,4871,7.6549,120.000,90.0143967,,,,,,,,,0.0000,-0.0147,0,0.00,0.00,0.00,0.00,0.1204735,,,,,,,,,,,4871,7.259,120.000,90.0,7.6523843,3.627,14.3853779,999.023,7.5421934,3.317,,,3.781590,3.580850,0.0,131.14,0.35074,0.00,0.00,765.6516113,-3.743996,,,,,,,,7.3375673,,1.0,7.6524,63.6,,,,120.0000,120.0000,-5.0000,0.00,0,0,2.5000,,,,0,0.00,0,0.00,20.40,23.53,,,,,,,,
,30358305.11,4871,7.5304,120.000,90.0143967,,,,,,,,,-0.0098,-0.0049,0,0.00,0.00,0.00,0.00,0.1085441,,,,,,,,,,,4871,7.122,120.000,90.0,7.5303960,3.561,14.3751411,999.023,7.4015503,3.246,,,3.781590,3.575965,0.0,129.67,0.34049,0.00,0.00,766.4766846,-3.355717,,,,,,,,7.3375673,,1.0,7.5253,63.6,,,,120.0000,120.0000,-5.0000,0.00,0,0,2.5000,,,,0,0.00,0,0.00,20.25,23.53,,,,,,,,
,30358400.13,4871,7.4017,120.000,90.0143967,,,,,,,,,-0.0049,-0.0049,0,0.00,0.00,0.00,0.00,0.1022241,,,,,,,,,,,4871,6.988,120.000,90.0,7.4016604,3.495,14.3654852,999.023,7.2666392,3.178,,,3.768173,3.566195,0.0,128.45,0.33728,0.00,0.00,766.4766846,-4.520555,,,,,,,,7.3131413,,1.0,7.4017,63.6,,,,120.0000,120.0000,-5.0000,0.00,0,0,2.5000,,,,0,0.00,0,0.00,20.44,23.53,,,,,,,,
,30358494.92,4871,7.2876,120.000,90.0143967,,,,,,,,,0.0000,-0.0147,0,0.00,0.00,0.00,0.00,0.0964764,,,,,,,,,,,4871,6.869,120.000,90.0,7.2875838,3.429,14.3571119,999.023,7.1240783,3.107,,,3.803058,3.575965,0.0,129.18,0.33763,0.00,0.00,766.4766846,-4.520555,,,,,,,,7.3766489,,1.0,7.2876,63.6,,,,120.0000,120.0000,-5.0000,0.00,0,0,2.5000,,,,0,0.00,0,0.00,20.23,23.53,,,,,,,,
,30358590.02,4871,7.1753,120.000,90.0143967,,,,,,,,,-0.0049,-0.0098,0,0.00,0.00,0.00,0.00,0.0939012,,,,,,,,,,,4871,6.785,120.000,90.0,7.1752977,3.376,14.3489809,999.023,7.0060015,3.046,,,3.808424,3.571080,0.0,128.69,0.33478,0.00,0.00,766.0641479,-3.355717,,,,,,,,7.3864193,,1.0,7.1741,63.6,,,,120.0000,120.0000,-5.0000,0.00,0,0,2.5000,,,,0,0.00,0,0.00,20.21,23.53,,,,,,,,
,30358684.97,4871,7.0696,120.000,90.0143967,,,,,,,,,-0.0147,-0.0049,0,0.00,0.00,0.00,0.00,0.0917698,,,,,,,,,,,4871,6.702,120.000,90.0,7.0695715,3.317,14.3423061,999.023,6.8870559,2.987,,,3.819158,3.580850,0.0,128.21,0.33194,0.00,0.00,766.0641479,-4.520555,,,,,,,,7.4059601,,1.0,7.0773,63.6,,,,120.0000,120.0000,-5.0000,0.00,0,0,2.5000,,,,0,0.00,0,0.00,20.20,23.53,,,,,,,,
,30358780.13,4871,6.9616,120.000,90.0143967,,,,,,,,,-0.0049,-0.0049,0,0.00,0.00,0.00,0.00,0.0908721,,,,,,,,,,,4871,6.584,120.000,90.0,6.9615736,3.261,14.3351917,999.023,6.7830544,2.934,,,3.816475,3.585735,0.0,126.74,0.32505,0.00,0.00,766.0641479,-4.520555,,,,,,,,7.4010749,,1.0,6.9616,63.6,,,,120.0000,120.0000,-5.0000,0.00,0,0,2.5000,,,,0,0.00,0,0.00,20.24,23.53,,,,,,,,
,30358874.94,4871,6.9800,120.000,90.0143967,,,,,,,,,-0.0049,-0.0147,0,0.00,0.00,0.00,0.00,0.0933300,,,,,,,,,,,4871,6.550,120.000,52.2,6.9799867,3.241,14.3382263,999.023,7.1329656,2.914,,,1.946134,3.849536,2.0,87.18,0.15226,0.00,0.00,617.5541382,-3.743996,,,,,,,,3.9960918,,1.0,6.9800,63.1,,,,120.0000,120.0000,-5.0000,0.00,0,0,2.5000,,,,0,0.00,0,0.00,20.03,23.53,,,,,,,,
,30358970.06,4871,6.8037,120.000,90.0143967,,,,,,,,,-0.0098,-0.0147,0,0.00,0.00,0.00,0.00,0.1006978,,,,,,,,,,,4871,6.162,120.000,21.9,6.8036857,3.007,14.3239965,999.023,7.0992670,3.061,,,0.218619,3.898388,2.0,136.02,0.37377,0.00,0.00,274.3309937,-4.132275,,,,,,,,0.2344895,,1.0,6.8037,63.1,,,,120.0000,120.0000,-5.0000,0.00,0,0,2.5000,,,,0,0.00,0,0.00,20.20,23.53,,,,,,,,
,30359065.09,4871,6.9966,120.000,90.0143967,,,,,,,,,-0.0098,-0.0147,0,0.00,0.00,0.00,0.00,0.1085441,,,,,,,,,,,4871,6.162,120.000,20.0,6.9966464,3.161,14.3394651,999.023,7.2739043,3.061,,,0.301262,3.903273,0.7,62.76,7.95619e-2,0.00,0.00,-37.1275063,-4.520555,,,,,,,,0.3908158,,1.0,6.9966,63.1,,,,120.0000,120.0000,-5.0000,0.00,0,0,2.5000,,,,0,0.00,0,0.00,19.89,23.53,,,,,,,,
,30359160.13,4871,6.9536,120.000,90.0143967,,,,,,,,,0.0000,-0.0147,0,0.00,0.00,0.00,0.00,0.1222726,,,,,,,,,,,4871,6.162,120.000,29.5,6.9536424,3.161,14.3379354,999.023,7.4151258,3.212,,,0.985901,3.893503,2.0,0.00,0.00,0.00,0.00,-46.2031136,-3.743996,,,,,,,,2.1104054,,1.0,6.9536,63.1,,,,120.0000,120.0000,-5.0000,0.00,0,0,2.5000,,,,0,0.00,0,0.00,-2.00e2,23.53,,,,,,,,
,30359254.97,4871,6.7434,120.000,90.0143967,,,,,,,,,-0.0147,-0.0147,0,0.00,0.00,0.00,0.00,0.1204735,,,,,,,,,,,4871,6.162,120.000,25.4,6.7434449,3.153,14.3242636,999.023,7.2177677,3.153,,,0.631160,3.903273,2.0,0.00,0.00,0.00,0.00,51.9785042,-4.520555,,,,,,,,1.1968734,,1.0,6.7434,63.1,,,,120.0000,120.0000,-5.0000,0.00,0,0,2.5000,,,,0,0.00,0,0.00,-2.00e2,23.53,,,,,,,,
,30359350.00,4871,6.5267,120.000,90.0143967,,,,,,,,,0.0000,-0.0049,0,0.00,0.00,0.00,0.00,0.1336915,,,,,,,,,,,4871,6.162,120.000,19.3,6.5264955,3.039,14.3122406,999.023,7.3985772,3.151,,,0.211405,3.908158,2.0,23.93,1.02297e-2,0.00,0.00,1.6501113,-4.520555,,,,,,,,0.2198339,,1.0,6.5265,63.1,,,,120.0000,120.0000,-5.0000,0.00,0,0,2.5000,,,,0,0.00,0,0.00,17.86,23.53,,,,,,,,
,30359445.13,4871,6.6021,120.000,90.0143967,,,,,,,,,0.0000,-0.0049,0,0.00,0.00,0.00,0.00,0.1461144,,,,,,,,,,,4871,6.162,120.000,20.1,6.6021447,3.039,14.3164177,999.023,7.5189548,3.151,,,0.277371,3.903273,2.0,0.00,0.00,0.00,0.00,-16.5011120,-3.743996,,,,,,,,0.3517343,,1.0,6.6021,63.1,,,,120.0000,120.0000,-5.0000,0.00,0,0,2.5000,,,,0,0.00,0,0.00,6.67,23.53,,,,,,,,
,30359540.16,4871,6.8749,120.000,90.0143967,,,,,,,,,-0.0098,-0.0049,0,0.00,0.00,0.00,0.00,0.1504174,,,,,,,,,,,4871,6.162,120.000,19.7,6.8748775,3.039,14.3326187,999.023,7.7656269,3.307,,,0.244406,3.893503,2.0,0.00,0.00,0.00,0.00,-12.7883615,-4.520555,,,,,,,,0.2882267,,1.0,6.8749,63.1,,,,120.0000,120.0000,-5.0000,0.00,0,0,2.5000,,,,0,0.00,0,0.00,6.67,23.53,,,,,,,,
,30359635.14,4871,7.2038,120.000,90.0143967,,,,,,,,,0.0000,-0.0147,0,0.00,0.00,0.00,0.00,0.1663318,,,,,,,,,,,4871,6.162,120.000,19.5,7.2038069,3.190,14.3614321,999.023,8.0920496,3.473,,,0.228152,3.893503,2.0,0.00,0.00,0.00,0.00,-10.7257233,-3.743996,,,,,,,,0.2540303,,1.0,7.2052,63.1,,,,120.0000,120.0000,-5.0000,0.00,0,0,2.5000,,,,0,0.00,0,0.00,6.67,23.53,,,,,,,,
,30359729.95,4870,6.1985,120.000,90.0143967,,,,,,,,,-0.0049,-0.0147,0,0.00,0.00,0.00,0.00,0.1377735,,,,,,,,,,,4870,5.813,120.000,54.0,6.1984653,2.843,14.2956429,999.023,6.5747447,2.814,,,3.797691,3.888618,2.0,0.00,0.00,0.00,0.00,293.7197876,-4.132275,,,,,,,,7.3668785,,1.0,6.1985,63.1,,,,120.0000,120.0000,-5.0000,0.00,0,0,2.5000,,,,0,0.00,0,0.00,6.67,23.53,,,,,,,,
,30359825.02,4870,2.7135,120.000,90.0143967,,,,,,,,,-0.0098,-0.0049,0,0.00,0.00,0.00,0.00,0.0447933,,,,,,,,,,,4870,2.566,120.000,57.9,2.7135100,0.855,14.2139740,999.023,2.7697127,0.777,,,4.106284,3.795799,2.0,0.00,0.00,0.00,0.00,690.1590576,-4.520555,,,,,,,,7.9286761,,1.0,2.7135,63.1,,,,120.0000,120.0000,-5.0000,0.00,0,0,2.5000,,,,0,0.00,0,0.00,6.67,23.53,,,,,,,,
,30359920.08,4870,2.4518,120.000,90.0143967,,,,,,,,,-0.0049,-0.0147,0,0.00,0.00,0.00,0.00,0.0366382,,,,,,,,,,,4870,2.324,120.000,60.7,2.4517777,0.708,14.2108088,999.023,2.5197275,0.645,,,4.127751,3.717636,2.0,0.00,0.00,0.00,0.00,735.9495850,-4.132275,,,,,,,,7.9677577,,1.0,2.4518,63.1,,,,120.0000,120.0000,-5.0000,0.00,0,0,2.5000,,,,0,0.00,0,0.00,6.67,23.53,,,,,,,,
,30360014.95,4870,2.2376,120.000,90.0143967,,,,,,,,,-0.0098,-0.0049,0,0.00,0.00,0.00,0.00,0.0311675,,,,,,,,,,,4870,2.126,120.000,81.6,2.2375693,0.589,14.2093716,999.023,2.3010259,0.537,,,3.899661,3.585735,2.0,0.00,0.00,0.00,0.00,765.6516113,-3.743996,,,,,,,,7.5525160,,1.0,2.2376,63.1,,,,120.0000,120.0000,-5.0000,0.00,0,0,2.5000,,,,0,0.00,0,0.00,6.67,23.53,,,,,,,,
,30360110.14,4870,2.2115,120.000,90.0143967,,,,,,,,,0.0000,-0.0049,0,0.00,0.00,0.00,0.00,0.0303368,,,,,,,,,,,4870,2.096,120.000,90.0,2.2115262,0.576,14.2088604,999.023,2.2705953,0.520,,,3.733289,3.556424,2.0,0.00,0.00,0.00,0.00,767.7142944,-3.743996,,,,,,,,7.2496338,,1.0,2.2115,63.1,,,,120.0000,120.0000,-5.0000,0.00,0,0,2.5000,,,,0,0.00,0,0.00,6.67,23.53,,,,,,,,
,30360204.92,4870,2.2093,120.000,90.0143967,,,,,,,,,-0.0147,-0.0147,0,0.00,0.00,0.00,0.00,0.0283184,,,,,,,,,,,4870,2.096,120.000,90.0,2.2093172,0.574,14.2087145,999.023,2.2611670,0.515,,,3.709138,3.546654,2.0,0.00,0.00,0.00,0.00,767.7142944,-3.743996,,,,,,,,7.2056670,,1.0,2.2093,63.1,,,,120.0000,120.0000,-5.0000,0.00,0,0,2.5000,,,,0,0.00,0,0.00,6.67,23.53,,,,,,,,
,30360300.03,4870,2.2093,120.000,90.0143967,,,,,,,,,-0.0049,-0.0098,0,0.00,0.00,0.00,0.00,0.0291133,,,,,,,,,,,4870,2.096,120.000,90.0,2.2093213,0.574,14.2087879,999.023,2.2529957,0.513,,,3.693038,3.556424,2.0,0.00,0.00,0.00,0.00,767.3016968,-4.520555,,,,,,,,7.1763558,,1.0,2.2093,63.1,,,,120.0000,120.0000,-5.0000,0.00,0,0,2.5000,,,,0,0.00,0,0.00,6.67,23.53,,,,,,,,
,30360394.95,4870,2.2076,120.000,90.0143967,,,,,,,,,-0.0049,-0.0049,0,0.00,0.00,0.00,0.00,0.0275428,,,,,,,,,,,4870,2.096,120.000,90.0,2.2076087,0.574,14.2083740,999.023,2.2387934,0.506,,,3.687671,3.561309,2.0,0.00,0.00,0.00,0.00,768.1267700,-4.520555,,,,,,,,7.1665854,,1.0,2.2076,63.1,,,,120.0000,120.0000,-5.0000,0.00,0,0,2.5000,,,,0,0.00,0,0.00,6.67,23.53,,,,,,,,
,30360490.08,4870,2.2063,120.000,90.0143967,,,,,,,,,-0.0147,-0.0098,0,0.00,0.00,0.00,0.00,0.0279282,,,,,,,,,,,4870,2.096,120.000,90.0,2.2063251,0.572,14.2091770,999.023,2.2315030,0.503,,,3.671570,3.546654,2.0,0.00,0.00,0.00,0.00,768.1267700,-3.355717,,,,,,,,7.1372743,,1.0,2.2063,62.9,,,,120.0000,120.0000,-5.0000,0.00,0,0,2.5000,,,,0,0.00,0,0.00,6.67,23.53,,,,,,,,
,30360584.97,4870,2.2039,120.000,90.0143967,,,,,,,,,-0.0098,-0.0147,0,0.00,0.00,0.00,0.00,0.0279282,,,,,,,,,,,4870,2.081,120.000,90.0,2.2038956,0.572,14.2087631,999.023,2.2250521,0.498,,,3.652786,3.551539,2.0,0.00,0.00,0.00,0.00,768.5393677,-3.355717,,,,,,,,7.1030779,,1.0,2.2039,62.9,,,,120.0000,120.0000,-5.0000,0.00,0,0,2.5000,,,,0,0.00,0,0.00,6.67,23.53,,,,,,,,
,30360680.03,4870,2.2032,120.000,90.0143967,,,,,,,,,-0.0098,-0.0049,0,0.00,0.00,0.00,0.00,0.0271623,,,,,,,,,,,4870,2.081,120.000,90.0,2.2032096,0.572,14.2086897,999.023,2.2212281,0.498,,,3.631319,3.541769,2.0,0.00,0.00,0.00,0.00,767.7142944,-3.355717,,,,,,,,7.0639963,,1.0,2.2032,62.9,,,,120.0000,120.0000,-5.0000,0.00,0,0,2.5000,,,,0,0.00,0,0.00,6.67,23.53,,,,,,,,
,30360775.16,4870,2.2005,120.000,90.0143967,,,,,,,,,0.0000,-0.0147,0,0.00,0.00,0.00,0.00,0.0267864,,,,,,,,,,,4870,2.081,120.000,90.0,2.2004516,0.569,14.2087145,999.023,2.2153175,0.493,,,3.617902,3.556424,2.0,0.00,0.00,0.00,0.00,768.5393677,-3.355717,,,,,,,,7.0395703,,1.0,2.2005,62.9,,,,120.0000,120.0000,-5.0000,0.00,0,0,2.5000,,,,0,0.00,0,0.00,6.67,23.53,,,,,,,,
,30360869.98,4870,2.1992,120.000,90.0143967,,,,,,,,,-0.0049,-0.0147,0,0.00,0.00,0.00,0.00,0.0264152,,,,,,,,,,,4870,2.081,120.000,90.0,2.1992166,0.569,14.2089090,999.023,2.2112484,0.493,,,3.596435,3.546654,2.0,0.00,0.00,0.00,0.00,768.1267700,-3.355717,,,,,,,,7.0004888,,1.0,2.1992,62.9,,,,120.0000,120.0000,-5.0000,0.00,0,0,2.5000,,,,0,0.00,0,0.00,6.67,23.53,,,,,,,,
,30360965.09,4870,2.1968,120.000,90.0143967,,,,,,,,,0.0000,-0.0049,0,0.00,0.00,0.00,0.00,0.0260486,,,,,,,,,,,4870,2.081,120.000,90.0,2.1968498,0.567,14.2090549,999.023,2.2049551,0.489,,,3.574967,3.541769,2.0,0.00,0.00,0.00,0.00,768.1267700,-3.743996,,,,,,,,6.9614067,,1.0,2.1968,62.9,,,,120.0000,120.0000,-5.0000,0.00,0,0,2.5000,,,,0,0.00,0,0.00,6.67,23.53,,,,,,,,
,30361059.97,4869,2.1978,120.000,90.0143967,,,,,,,,,-0.0098,-0.0098,0,0.00,0.00,0.00,0.00,0.0267864,,,,,,,,,,,4869,2.200,120.000,90.0,2.1977723,0.567,14.2084465,999.023,2.2018008,0.489,,,3.583017,3.551539,2.0,15.63,4.39012e-3,0.00,0.00,768.9518433,-4.520555,,,,,,,,6.9760623,,1.0,2.1978,62.9,,,,120.0000,120.0000,-5.0000,0.00,0,0,2.5000,,,,0,0.00,0,0.00,17.97,23.53,,,,,,,,
,30361154.97,4866,2.2327,120.000,90.0143967,,,,,,,,,-0.0098,-0.0049,0,0.00,0.00,0.00,0.00,0.0260486,,,,,,,,,,,4866,2.217,120.000,49.6,2.2327409,0.567,14.2088604,999.023,2.2468574,0.489,,,0.318540,3.619932,0.0,18.80,6.59710e-3,0.00,0.00,759.8762207,-4.520555,,,,,,,,0.4347826,,1.0,2.2395,62.9,,,,120.0000,120.0000,-5.0000,0.00,0,0,2.5000,,,,0,0.00,0,0.00,17.73,23.53,,,,,,,,
,30361250.09,4870,2.7148,120.000,90.0143967,,,,,,,,,0.0000,-0.0147,0,0.00,0.00,0.00,0.00,0.0356657,,,,,,,,,,,4870,2.535,120.000,57.4,2.7147734,0.840,14.2133656,999.023,2.7127521,0.733,,,3.819158,3.795799,0.0,0.00,0.00,0.00,0.00,687.2713623,-3.355717,,,,,,,,7.4059601,,1.0,2.7148,62.9,,,,120.0000,120.0000,-5.0000,0.00,0,0,2.5000,,,,0,0.00,0,0.00,16.00,23.53,,,,,,,,
,30361345.05,4866,2.7631,120.000,90.0143967,,,,,,,,,-0.0049,-0.0049,0,0.00,0.00,0.00,0.00,0.0333427,,,,,,,,,,,4866,2.739,120.000,53.3,2.7631452,0.852,14.2139492,999.023,2.7293496,0.723,,,2.367430,3.795799,0.0,114.29,0.26297,0.00,0.00,686.8588257,-3.355717,,,,,,,,4.7630677,,1.0,2.7671,62.9,,,,120.0000,120.0000,-5.0000,0.00,0,0,2.5000,,,,0,0.00,0,0.00,20.05,23.53,,,,,,,,
,30361440.11,4866,3.0088,120.000,90.0143967,,,,,,,,,-0.0147,-0.0049,0,0.00,0.00,0.00,0.00,0.0402485,,,,,,,,,,,4866,3.055,120.000,55.6,3.0088406,1.026,14.2169933,999.023,3.0016620,0.879,,,3.422013,3.844651,0.0,20.51,6.68061e-3,0.00,0.00,614.2539063,-3.743996,,,,,,,,6.6829505,,1.0,3.0088,62.9,,,,120.0000,120.0000,-5.0000,0.00,0,0,2.5000,,,,0,0.00,0,0.00,17.50,23.53,,,,,,,,
,30361535.05,4870,3.5124,120.000,90.0143967,,,,,,,,,-0.0049,-0.0147,0,0.00,0.00,0.00,0.00,0.0532058,,,,,,,,,,,4870,3.371,120.000,26.8,3.5123873,1.236,14.2229834,999.023,3.4900458,1.124,,,0.301262,3.873962,0.0,88.89,0.15850,0.00,0.00,435.6293945,-3.743996,,,,,,,,0.3908158,,1.0,3.5124,62.9,,,,120.0000,120.0000,-5.0000,0.00,0,0,2.5000,,,,0,0.00,0,0.00,20.06,23.53,,,,,,,,
,30361630.13,4870,3.5628,120.000,90.0143967,,,,,,,,,0.0000,-0.0098,0,0.00,0.00,0.00,0.00,0.0539010,,,,,,,,,,,4870,3.688,120.000,47.0,3.5628157,1.297,14.2243471,999.023,3.5365407,1.180,,,1.691210,3.873962,0.0,80.10,0.13010,0.00,0.00,412.1152649,-3.743996,,,,,,,,3.5319982,,1.0,3.5628,62.9,,,,120.0000,120.0000,-5.0000,0.00,0,0,2.5000,,,,0,0.00,0,0.00,20.28,23.53,,,,,,,,
,30361725.14,4870,4.0823,120.000,90.0143967,,,,,,,,,-0.0098,-0.0049,0,0.00,0.00,0.00,0.00,0.0724184,,,,,,,,,,,4870,4.005,120.000,21.6,4.0823145,1.578,14.2327194,999.023,4.0443358,1.368,,,0.310935,3.888618,0.7,91.09,0.16888,0.00,0.00,110.9699860,-4.132275,,,,,,,,0.4152418,,1.0,4.0823,62.9,,,,120.0000,120.0000,-5.0000,0.00,0,0,2.5000,,,,0,0.00,0,0.00,20.11,23.53,,,,,,,,
,30361819.97,4870,4.2612,120.000,90.0143967,,,,,,,,,-0.0049,-0.0049,0,0.00,0.00,0.00,0.00,0.0825996,,,,,,,,,,,4870,4.322,120.000,23.4,4.2611637,1.656,14.2360067,999.023,4.2333012,1.507,,,0.377104,3.908158,0.7,80.34,0.13010,0.00,0.00,-32.5896988,-4.132275,,,,,,,,0.5520273,,1.0,4.2612,62.9,,,,120.0000,120.0000,-5.0000,0.00,0,0,2.5000,,,,0,0.00,0,0.00,20.28,23.53,,,,,,,,
,30361914.98,4870,4.5220,120.000,90.0143967,,,,,,,,,-0.0049,-0.0049,0,0.00,0.00,0.00,0.00,0.0751926,,,,,,,,,,,4870,4.638,120.000,38.4,4.5220490,1.827,14.2409954,999.023,4.4193845,1.583,,,2.678707,3.908158,0.7,175.82,0.62702,0.00,0.00,-181.5122375,-3.355717,,,,,,,,5.3297510,,1.0,4.5231,62.9,,,,120.0000,120.0000,-5.0000,0.00,0,0,2.5000,,,,0,0.00,0,0.00,20.28,23.53,,,,,,,,
,30362010.02,4870,6.7818,120.000,90.0143967,,,,,,,,,-0.0049,-0.0147,0,0.00,0.00,0.00,0.00,0.0574997,,,,,,,,,,,4870,4.955,120.000,47.8,6.7817602,3.075,14.3180208,999.023,5.1272650,2.025,,,3.778907,3.913043,0.7,227.84,1.11313,0.00,0.00,-209.1515961,-3.355717,,,,,,,,7.3326821,,1.0,6.7818,62.9,,,,120.0000,120.0000,-5.0000,0.00,0,0,2.5000,,,,0,0.00,0,0.00,20.38,23.53,,,,,,,,
,30362105.11,4866,5.2710,120.000,90.0143967,,,,,,,,,-0.0098,-0.0049,0,0.00,0.00,0.00,0.00,0.0645222,,,,,,,,,,,4866,5.272,120.000,37.3,5.2709632,2.218,14.2599497,999.023,5.1182380,2.003,,,2.638456,3.898388,0.7,60.32,7.29290e-2,0.00,0.00,-106.0196533,-3.743996,,,,,,,,5.2564731,,1.0,5.2719,62.9,,,,120.0000,120.0000,-5.0000,0.00,0,0,2.5000,,,,0,0.00,0,0.00,20.05,23.53,,,,,,,,
,30362199.91,4866,5.5934,120.000,90.0143967,,,,,,,,,-0.0049,-0.0147,0,0.00,0.00,0.00,0.00,0.0738563,,,,,,,,,,,4866,5.588,120.000,31.9,5.5934005,2.447,14.2709913,999.023,5.4717278,2.103,,,1.720728,3.898388,0.7,52.26,5.48884e-2,0.00,0.00,-68.8921432,-3.355717,,,,,,,,3.5857353,,1.0,5.5979,62.9,,,,120.0000,120.0000,-5.0000,0.00,0,0,2.5000,,,,0,0.00,0,0.00,20.10,23.53,,,,,,,,
,30362295.03,4866,5.9202,120.000,90.0143967,,,,,,,,,-0.0049,-0.0098,0,0.00,0.00,0.00,0.00,0.0850512,,,,,,,,,,,4866,5.904,120.000,26.5,5.9202151,2.570,14.2836103,999.023,5.8218393,2.318,,,0.841289,3.913043,0.7,41.51,3.29557e-2,0.00,0.00,-24.3391399,-4.520555,,,,,,,,1.7293600,,1.0,5.9202,62.9,,,,120.0000,120.0000,-5.0000,0.00,0,0,2.5000,,,,0,0.00,0,0.00,19.12,23.53,,,,,,,,
,30362389.94,4866,6.2225,120.000,90.0143967,,,,,,,,,-0.0098,-0.0147,0,0.00,0.00,0.00,0.00,0.0902938,,,,,,,,,,,4866,6.221,120.000,21.9,6.2225194,2.697,14.2973928,999.023,6.1531100,2.433,,,0.404654,3.903273,0.7,36.14,2.47183e-2,0.00,0.00,-13.2008905,-3.355717,,,,,,,,0.6301906,,1.0,6.2225,62.9,,,,120.0000,120.0000,-5.0000,0.00,0,0,2.5000,,,,0,0.00,0,0.00,18.92,23.53,,,,,,,,
,30362485.03,4866,6.5392,120.000,90.0143967,,,,,,,,,-0.0049,-0.0049,0,0.00,0.00,0.00,0.00,0.0915950,,,,,,,,,,,4866,6.538,120.000,20.5,6.5392303,2.831,14.3148384,999.023,6.4828191,2.682,,,0.303819,3.903273,0.7,31.01,1.89383e-2,0.00,0.00,-9.0756121,-4.132275,,,,,,,,0.3957010,,1.0,6.5392,62.7,,,,120.0000,120.0000,-5.0000,0.00,0,0,2.5000,,,,0,0.00,0,0.00,19.69,23.53,,,,,,,,
,30362580.03,4866,6.8534,120.000,90.0143967,,,,,,,,,-0.0049,-0.0098,0,0.00,0.00,0.00,0.00,0.0936077,,,,,,,,,,,4866,6.854,120.000,20.3,6.8533978,3.122,14.3745594,999.023,6.8020601,2.816,,,0.287106,3.898388,0.7,30.28,1.73815e-2,0.00,0.00,-6.6004453,-3.743996,,,,,,,,0.3663898,,1.0,6.8534,62.7,,,,120.0000,120.0000,-5.0000,0.00,0,0,2.5000,,,,0,0.00,0,0.00,18.96,23.53,,,,,,,,
,30362675.19,4866,7.1717,120.000,90.0143967,,,,,,,,,0.0000,-0.0147,0,0.00,0.00,0.00,0.00,0.0969328,,,,,,,,,,,4866,7.171,120.000,20.3,7.1717196,3.278,14.5104666,999.023,7.1273999,2.958,,,0.280730,3.903273,0.7,28.33,1.47480e-2,0.00,0.00,-6.1879172,-4.132275,,,,,,,,0.3566194,,1.0,7.1717,62.7,,,,120.0000,120.0000,-5.0000,0.00,0,0,2.5000,,,,0,0.00,0,0.00,19.40,23.53,,,,,,,,
,30362770.03,4866,7.4897,120.000,90.0143967,,,,,,,,,-0.0147,-0.0147,0,0.00,0.00,0.00,0.00,0.1022241,,,,,,,,,,,4866,7.487,120.000,20.3,7.4896555,3.442,14.5338936,999.023,7.4474616,3.105,,,0.287106,3.898388,0.7,26.86,1.34507e-2,0.00,0.00,-5.3628616,-3.743996,,,,,,,,0.3663898,,1.0,7.4897,62.7,,,,120.0000,120.0000,-5.0000,0.00,0,0,2.5000,,,,0,0.00,0,0.00,18.64,23.53,,,,,,,,
,30362865.02,4866,7.8060,120.000,90.0143967,,,,,,,,,-0.0098,-0.0049,0,0.00,0.00,0.00,0.00,0.1135172,,,,,,,,,,,4866,7.804,120.000,20.3,7.8060107,3.442,14.5608587,999.023,7.7617927,3.258,,,0.287106,3.903273,0.7,25.15,1.16732e-2,0.00,0.00,-4.5378060,-3.355717,,,,,,,,0.3663898,,1.0,7.8060,62.7,,,,120.0000,120.0000,-5.0000,0.00,0,0,2.5000,,,,0,0.00,0,0.00,18.45,23.53,,,,,,,,
,30362960.06,4866,8.1215,120.000,90.0143967,,,,,,,,,-0.0049,-0.0147,0,0.00,0.00,0.00,0.00,0.1204735,,,,,,,,,,,4866,8.122,120.000,20.3,8.1215124,3.613,14.5911169,999.023,8.0796518,3.422,,,0.283973,3.893503,0.7,25.40,1.17865e-2,0.00,0.00,-2.4751670,-4.520555,,,,,,,,0.3615046,,1.0,8.1215,62.7,,,,120.0000,120.0000,-5.0000,0.00,0,0,2.5000,,,,0,0.00,0,0.00,18.27,23.53,,,,,,,,
,30363054.95,4866,8.4356,120.000,90.0143967,,,,,,,,,-0.0098,-0.0049,0,0.00,0.00,0.00,0.00,0.1297189,,,,,,,,,,,4866,8.437,120.000,23.3,8.4367180,3.793,14.6248026,999.023,8.3901577,3.593,,,0.351759,3.908158,0.7,31.99,1.99255e-2,0.00,0.00,15.2635298,-4.132275,,,,,,,,0.4885198,,1.0,8.4367,62.7,,,,120.0000,120.0000,-5.0000,0.00,0,0,2.5000,,,,0,0.00,0,0.00,19.09,23.53,,,,,,,,
,30363150.09,4866,8.7534,120.000,90.0143967,,,,,,,,,-0.0098,-0.0049,0,0.00,0.00,0.00,0.00,0.1419047,,,,,,,,,,,4866,8.755,120.000,23.5,8.7540464,3.981,14.6623907,999.023,8.7122755,3.771,,,0.360588,3.898388,0.7,35.41,2.37848e-2,0.00,0.00,25.1641960,-4.132275,,,,,,,,0.5031754,,1.0,8.7540,62.7,,,,120.0000,120.0000,-5.0000,0.00,0,0,2.5000,,,,0,0.00,0,0.00,18.97,23.53,,,,,,,,
,30363245.08,4866,9.0708,120.000,90.0143967,,,,,,,,,-0.0147,-0.0147,0,0.00,0.00,0.00,0.00,0.1526069,,,,,,,,,,,4866,9.071,120.000,23.5,9.0707788,4.179,14.7038975,999.023,9.0352392,3.771,,,0.360588,3.893503,0.7,39.80,3.06264e-2,0.00,0.00,25.5767231,-3.743996,,,,,,,,0.5031754,,1.0,9.0708,62.7,,,,120.0000,120.0000,-5.0000,0.00,0,0,2.5000,,,,0,0.00,0,0.00,19.33,23.53,,,,,,,,
,30363340.06,4866,9.3866,120.000,90.0143967,,,,,,,,,-0.0049,-0.0098,0,0.00,0.00,0.00,0.00,0.1639708,,,,,,,,,,,4866,9.388,120.000,23.5,9.3866367,4.179,14.7498074,999.023,9.3609819,3.959,,,0.363229,3.898388,0.7,43.96,3.75784e-2,0.00,0.00,19.8013363,-3.355717,,,,,,,,0.5080606,,1.0,9.3866,62.7,,,,120.0000,120.0000,-5.0000,0.00,0,0,2.5000,,,,0,0.00,0,0.00,19.45,23.53,,,,,,,,
,30363435.08,4866,9.7040,120.000,90.0143967,,,,,,,,,-0.0049,-0.0098,0,0.00,0.00,0.00,0.00,0.1687238,,,,,,,,,,,4866,9.705,120.000,21.2,9.7039509,4.387,14.8010149,999.023,9.6891537,4.157,,,0.348493,3.908158,0.7,48.60,4.62931e-2,0.00,0.00,4.9503341,-3.743996,,,,,,,,0.4836346,,1.0,9.7052,62.7,,,,120.0000,120.0000,-5.0000,0.00,0,0,2.5000,,,,0,0.00,0,0.00,19.60,23.53,,,,,,,,
,30363530.13,4866,10.0224,120.000,90.0143967,,,,,,,,,0.0000,-0.0098,0,0.00,0.00,0.00,0.00,0.1811431,,,,,,,,,,,4866,10.021,120.000,20.6,10.0223894,4.607,14.8567114,999.023,10.0169563,4.365,,,0.314558,3.893503,0.7,46.89,4.29468e-2,0.00,0.00,-12.3758345,-4.132275,,,,,,,,0.4250122,,1.0,10.0224,62.7,,,,120.0000,120.0000,-5.0000,0.00,0,0,2.5000,,,,0,0.00,0,0.00,19.54,23.53,,,,,,,,
,30363624.92,4866,10.3379,120.000,90.0143967,,,,,,,,,-0.0049,-0.0098,0,0.00,0.00,0.00,0.00,0.1917015,,,,,,,,,,,4866,10.338,120.000,20.6,10.3379116,4.607,14.9178658,999.023,10.3492184,4.365,,,0.316504,3.903273,0.7,44.69,3.87505e-2,0.00,0.00,-10.3131952,-3.743996,,,,,,,,0.4298974,,1.0,10.3390,62.7,,,,120.0000,120.0000,-5.0000,0.00,0,0,2.5000,,,,0,0.00,0,0.00,19.40,23.53,,,,,,,,
,30363720.13,4866,10.6559,120.000,90.0143967,,,,,,,,,-0.0098,-0.0147,0,0.00,0.00,0.00,0.00,0.2057512,,,,,,,,,,,4866,10.654,120.000,20.2,10.6558867,4.836,14.9846382,999.023,10.7001448,4.582,,,0.283973,3.903273,0.7,42.98,3.56936e-2,0.00,0.00,-11.5507784,-3.355717,,,,,,,,0.3615046,,1.0,10.6559,62.7,,,,120.0000,120.0000,-5.0000,0.00,0,0,2.5000,,,,0,0.00,0,0.00,19.32,23.53,,,,,,,,
,30363814.95,4866,10.9714,120.000,90.0143967,,,,,,,,,-0.0098,-0.0147,0,0.00,0.00,0.00,0.00,0.2177116,,,,,,,,,,,4866,10.971,120.000,20.2,10.9714136,5.056,15.0575819,999.023,11.0669575,4.812,,,0.277371,3.903273,0.7,42.25,3.47690e-2,0.00,0.00,-7.4255009,-4.132275,,,,,,,,0.3517343,,1.0,10.9726,62.7,,,,120.0000,120.0000,-5.0000,0.00,0,0,2.5000,,,,0,0.00,0,0.00,19.95,23.53,,,,,,,,
,30363909.91,4866,11.2869,120.000,90.0143967,,,,,,,,,-0.0098,-0.0049,0,0.00,0.00,0.00,0.00,0.2303486,,,,,,,,,,,4866,11.287,120.000,20.2,11.2883635,5.056,15.1352224,999.023,11.4412966,4.812,,,0.277371,3.898388,0.7,42.25,3.45692e-2,0.00,0.00,-4.1252780,-3.355717,,,,,,,,0.3517343,,1.0,11.2884,62.7,,,,120.0000,120.0000,-5.0000,0.00,0,0,2.5000,,,,0,0.00,0,0.00,19.37,23.53,,,,,,,,
,30364004.94,4866,11.6036,120.000,90.0143967,,,,,,,,,-0.0049,-0.0049,0,0.00,0.00,0.00,0.00,0.2402911,,,,,,,,,,,4866,11.604,120.000,20.2,11.6044531,5.300,15.2201729,999.023,11.8147297,5.032,,,0.277371,3.903273,0.7,42.74,3.65346e-2,0.00,0.00,-3.7127504,-4.520555,,,,,,,,0.3517343,,1.0,11.6045,62.7,,,,120.0000,120.0000,-5.0000,0.00,0,0,2.5000,,,,0,0.00,0,0.00,20.00,23.53,,,,,,,,
,30364100.08,4866,11.9222,120.000,90.0143967,,,,,,,,,-0.0049,-0.0049,0,0.00,0.00,0.00,0.00,0.2506481,,,,,,,,,,,4866,11.922,120.000,20.0,11.9222164,5.300,15.3113985,999.023,12.1847372,5.276,,,0.258819,3.898388,0.7,42.74,3.67434e-2,0.00,0.00,-4.1252780,-3.355717,,,,,,,,0.3175379,,1.0,11.9222,62.7,,,,120.0000,120.0000,-5.0000,0.00,0,0,2.5000,,,,0,0.00,0,0.00,19.43,23.53,,,,,,,,
,30364195.02,4866,12.2379,120.000,90.0143967,,,,,,,,,-0.0049,-0.0049,0,0.00,0.00,0.00,0.00,0.2688711,,,,,,,,,,,4866,12.238,120.000,20.0,12.2378693,5.545,15.4091520,999.023,12.5590296,5.276,,,0.258819,3.908158,0.7,42.74,3.47690e-2,0.00,0.00,-3.3002226,-4.520555,,,,,,,,0.3175379,,1.0,12.2379,62.7,,,,120.0000,120.0000,-5.0000,0.00,0,0,2.5000,,,,0,0.00,0,0.00,19.26,23.53,,,,,,,,
,30364290.08,4866,12.5552,120.000,90.0143967,,,,,,,,,0.0000,-0.0147,0,0.00,0.00,0.00,0.00,0.2883530,,,,,,,,,,,4866,12.554,120.000,20.0,12.5551519,5.545,15.5138626,999.023,12.9305744,5.520,,,0.263759,3.903273,0.7,42.98,3.62185e-2,0.00,0.00,-3.7127504,-4.520555,,,,,,,,0.3273083,,1.0,12.5552,62.7,,,,120.0000,120.0000,-5.0000,0.00,0,0,2.5000,,,,0,0.00,0,0.00,19.61,23.53,,,,,,,,
,30364385.11,4866,12.8718,120.000,90.0143967,,,,,,,,,-0.0049,-0.0147,0,0.00,0.00,0.00,0.00,0.2924059,,,,,,,,,,,4866,12.872,120.000,20.0,12.8717985,5.813,15.6249142,999.023,13.3007727,5.789,,,0.256378,3.893503,0.7,43.22,3.74800e-2,0.00,0.00,-2.8876946,-3.743996,,,,,,,,0.3126527,,1.0,12.8718,62.7,,,,120.0000,120.0000,-5.0000,0.00,0,0,2.5000,,,,0,0.00,0,0.00,20.06,23.53,,,,,,,,
,30364480.02,4866,13.1877,120.000,90.0143967,,,,,,,,,-0.0049,-0.0147,0,0.00,0.00,0.00,0.00,0.3048327,,,,,,,,,,,4866,13.188,120.000,20.0,13.1877117,5.813,15.7432623,999.023,13.6655102,5.789,,,0.258819,3.913043,0.7,43.96,3.86521e-2,0.00,0.00,-2.0626390,-4.520555,,,,,,,,0.3175379,,1.0,13.1889,62.7,,,,120.0000,120.0000,-5.0000,0.00,0,0,2.5000,,,,0,0.00,0,0.00,20.00,23.53,,,,,,,,
,30364575.09,4866,13.5037,120.000,90.0143967,,,,,,,,,0.0000,-0.0147,0,0.00,0.00,0.00,0.00,0.3220400,,,,,,,,,,,4866,13.504,120.000,20.0,13.5037174,6.082,15.8694534,999.023,14.0404749,6.058,,,0.258819,3.908158,0.7,44.44,3.85388e-2,0.00,0.00,-3.3002226,-3.743996,,,,,,,,0.3175379,,1.0,13.5055,62.7,,,,120.0000,120.0000,-5.0000,0.00,0,0,2.5000,,,,0,0.00,0,0.00,19.51,23.53,,,,,,,,
,30364669.98,4866,13.8206,120.000,90.0143967,,,,,,,,,-0.0049,-0.0098,0,0.00,0.00,0.00,0.00,0.3309737,,,,,,,,,,,4866,13.820,120.000,20.0,13.8217201,6.082,16.0008640,999.023,14.4140491,6.058,,,0.263759,3.903273,0.7,44.44,3.87505e-2,0.00,0.00,-3.3002226,-4.520555,,,,,,,,0.3273083,,1.0,13.8217,62.7,,,,120.0000,120.0000,-5.0000,0.00,0,0,2.5000,,,,0,0.00,0,0.00,19.40,23.53,,,,,,,,
,30364765.09,4866,14.1381,120.000,90.0143967,,,,,,,,,0.0000,-0.0049,0,0.00,0.00,0.00,0.00,0.3355254,,,,,,,,,,,4866,14.138,120.000,20.0,14.1400986,6.375,16.1419792,999.023,14.7894144,6.351,,,0.261279,3.908158,0.7,44.44,3.85388e-2,0.00,0.00,-3.3002226,-3.743996,,,,,,,,0.3224231,,1.0,14.1401,62.7,,,,120.0000,120.0000,-5.0000,0.00,0,0,2.5000,,,,0,0.00,0,0.00,19.51,23.53,,,,,,,,
,30364860.08,4866,14.4539,120.000,90.0143967,,,,,,,,,-0.0098,-0.0147,0,0.00,0.00,0.00,0.00,0.3309737,,,,,,,,,,,4866,14.454,120.000,20.0,14.4550905,6.375,16.2890987,999.023,15.1643410,6.351,,,0.261279,3.898388,0.7,44.69,3.98421e-2,0.00,0.00,-3.3002226,-3.355717,,,,,,,,0.3224231,,1.0,14.4551,62.7,,,,120.0000,120.0000,-5.0000,0.00,0,0,2.5000,,,,0,0.00,0,0.00,19.40,23.53,,,,,,,,
,30364955.05,4866,14.7732,120.000,90.0143967,,,,,,,,,0.0000,-0.0147,0,0.00,0.00,0.00,0.00,0.3448015,,,,,,,,,,,4866,14.771,120.000,20.0,14.7732496,6.693,16.4472866,999.023,15.5323362,6.668,,,0.261279,3.908158,0.7,42.00,3.48823e-2,0.00,0.00,-2.0626390,-3.743996,,,,,,,,0.3224231,,1.0,14.7732,62.7,,,,120.0000,120.0000,-5.0000,0.00,0,0,2.5000,,,,0,0.00,0,0.00,19.77,23.53,,,,,,,,
,30365050.11,4869,14.9986,120.000,90.0143967,,,,,,,,,-0.0049,-0.0049,0,0.00,0.00,0.00,0.00,0.3543125,,,,,,,,,,,4869,15.000,120.000,20.0,14.9986305,6.693,16.5639820,999.023,15.8621483,6.668,,,0.261279,3.903273,0.7,41.27,3.32659e-2,0.00,0.00,2.0626390,-4.520555,,,,,,,,0.3224231,,1.0,14.9986,62.7,,,,120.0000,120.0000,-5.0000,0.00,0,0,2.5000,,,,0,0.00,0,0.00,19.53,23.53,,,,,,,,
,30365145.13,4865,15.0010,120.000,90.0143967,,,,,,,,,-0.0098,-0.0147,0,0.00,0.00,0.00,0.00,0.3448015,,,,,,,,,,,4865,15.000,120.000,20.0,15.0010033,6.693,16.5647945,999.023,15.9645128,6.668,,,0.258819,3.908158,0.7,40.78,3.28722e-2,0.00,0.00,-0.8250557,-3.743996,,,,,,,,0.3175379,,1.0,15.0010,62.7,,,,120.0000,120.0000,-5.0000,0.00,0,0,2.5000,,,,0,0.00,0,0.00,19.47,23.53,,,,,,,,
,30365240.02,4865,15.0009,120.000,90.0143967,,,,,,,,,-0.0147,-0.0098,0,0.00,0.00,0.00,0.00,0.3640639,,,,,,,,,,,4865,15.000,120.000,20.0,15.0009050,6.693,16.5644779,999.023,16.0405254,6.668,,,0.263759,3.903273,0.7,39.80,3.15987e-2,0.00,0.00,-2.8876946,-3.355717,,,,,,,,0.3273083,,1.0,14.9998,62.7,,,,120.0000,120.0000,-5.0000,0.00,0,0,2.5000,,,,0,0.00,0,0.00,19.94,23.53,,,,,,,,
,30365335.00,4865,15.0009,120.000,90.0143967,,,,,,,,,-0.0049,-0.0147,0,0.00,0.00,0.00,0.00,0.3640639,,,,,,,,,,,4865,15.000,120.000,20.0,15.0009050,6.693,16.5653343,999.023,16.1117306,6.668,,,0.263759,3.908158,0.7,38.34,2.85626e-2,0.00,0.00,-3.7127504,-3.355717,,,,,,,,0.3273083,,1.0,15.0009,62.7,,,,120.0000,120.0000,-5.0000,0.00,0,0,2.5000,,,,0,0.00,0,0.00,19.43,23.53,,,,,,,,
,30365429.91,4865,14.9997,120.000,90.0143967,,,,,,,,,0.0000,-0.0098,0,0.00,0.00,0.00,0.00,0.3640639,,,,,,,,,,,4865,15.000,120.000,20.0,14.9996834,6.693,16.5646343,999.023,16.1793613,6.668,,,0.261279,3.913043,0.7,36.63,2.54997e-2,0.00,0.00,-3.3002226,-4.132275,,,,,,,,0.3224231,,1.0,14.9997,62.7,,,,120.0000,120.0000,-5.0000,0.00,0,0,2.5000,,,,0,0.00,0,0.00,20.00,23.53,,,,,,,,
,30365525.16,4865,15.0001,120.000,90.0143967,,,,,,,,,0.0000,-0.0098,0,0.00,0.00,0.00,0.00,0.3640639,,,,,,,,,,,4865,15.000,120.000,20.0,15.0000591,6.693,16.5648155,999.023,16.2408638,6.986,,,0.261279,3.913043,0.7,35.65,2.52551e-2,0.00,0.00,-2.8876946,-3.743996,,,,,,,,0.3224231,,1.0,15.0001,62.7,,,,120.0000,120.0000,-5.0000,0.00,0,0,2.5000,,,,0,0.00,0,0.00,19.87,23.53,,,,,,,,
,30365620.08,4865,14.9994,120.000,90.0143967,,,,,,,,,-0.0098,-0.0147,0,0.00,0.00,0.00,0.00,0.3895306,,,,,,,,,,,4865,15.000,120.000,20.0,14.9993591,6.693,16.5655365,999.023,16.3042011,6.986,,,0.261279,3.898388,0.7,34.92,2.34567e-2,0.00,0.00,-2.0626390,-3.355717,,,,,,,,0.3224231,,1.0,14.9994,62.7,,,,120.0000,120.0000,-5.0000,0.00,0,0,2.5000,,,,0,0.00,0,0.00,19.24,23.53,,,,,,,,
,30365715.13,4865,15.0006,120.000,90.0143967,,,,,,,,,-0.0147,-0.0049,0,0.00,0.00,0.00,0.00,0.3895306,,,,,,,,,,,4865,15.000,120.000,20.0,15.0025702,6.693,16.5653343,999.023,16.3639565,6.986,,,0.256378,3.898388,0.7,33.94,2.28006e-2,0.00,0.00,-2.4751670,-3.355717,,,,,,,,0.3126527,,1.0,15.0026,62.7,,,,120.0000,120.0000,-5.0000,0.00,0,0,2.5000,,,,0,0.00,0,0.00,19.79,23.53,,,,,,,,
,30365810.16,4865,14.9995,120.000,90.0143967,,,,,,,,,-0.0049,-0.0147,0,0.00,0.00,0.00,0.00,0.3791538,,,,,,,,,,,4865,15.000,120.000,20.0,14.9994535,6.693,16.5651321,999.023,16.4246998,6.986,,,0.261279,3.917929,0.7,32.72,2.03818e-2,0.00,0.00,-1.6501113,-3.743996,,,,,,,,0.3224231,,1.0,14.9995,62.7,,,,120.0000,120.0000,-5.0000,0.00,0,0,2.5000,,,,0,0.00,0,0.00,19.03,23.53,,,,,,,,
,30365905.11,4865,15.0003,120.000,90.0143967,,,,,,,,,-0.0049,-0.0049,0,0.00,0.00,0.00,0.00,0.3895306,,,,,,,,,,,4865,15.000,120.000,20.0,15.0003204,6.693,16.5651550,999.023,16.4844341,6.986,,,0.263759,3.908158,0.7,31.50,1.88519e-2,0.00,0.00,-3.3002226,-3.743996,,,,,,,,0.3273083,,1.0,15.0002,62.7,,,,120.0000,120.0000,-5.0000,0.00,0,0,2.5000,,,,0,0.00,0,0.00,19.00,23.53,,,,,,,,
,30365999.98,4865,15.0001,120.000,90.0143967,,,,,,,,,-0.0049,-0.0147,0,0.00,0.00,0.00,0.00,0.3895306,,,,,,,,,,,4865,15.000,120.000,22.3,15.0000639,6.693,16.5656948,999.023,16.5262585,6.986,,,0.293057,3.903273,0.7,31.75,1.89980e-2,0.00,0.00,-0.4125278,-3.743996,,,,,,,,0.3761602,,1.0,15.0001,62.7,,,,120.0000,120.0000,-5.0000,0.00,0,0,2.5000,,,,0,0.00,0,0.00,18.85,23.53,,,,,,,,
,30366094.91,4865,14.9995,120.000,90.0143967,,,,,,,,,-0.0098,-0.0049,0,0.00,0.00,0.00,0.00,0.3895306,,,,,,,,,,,4865,15.000,120.000,22.3,15.0000162,6.693,16.5652447,999.023,16.5532284,6.986,,,0.280730,3.908158,0.7,32.72,2.03818e-2,0.00,0.00,4.5378060,-3.355717,,,,,,,,0.3566194,,1.0,15.0000,62.5,,,,120.0000,120.0000,-5.0000,0.00,0,0,2.5000,,,,0,0.00,0,0.00,19.03,23.53,,,,,,,,
,30366190.00,4865,14.9998,120.000,90.0143967,,,,,,,,,-0.0049,-0.0147,0,0.00,0.00,0.00,0.00,0.3895306,,,,,,,,,,,4865,15.000,120.000,22.3,14.9997568,6.693,16.5655823,999.023,16.5812073,6.986,,,0.287106,3.903273,0.7,34.43,2.35492e-2,0.00,0.00,1.6501113,-4.132275,,,,,,,,0.3663898,,1.0,14.9998,62.5,,,,120.0000,120.0000,-5.0000,0.00,0,0,2.5000,,,,0,0.00,0,0.00,19.86,23.53,,,,,,,,
,30366284.94,4865,14.9995,120.000,90.0143967,,,,,,,,,-0.0049,-0.0049,0,0.00,0.00,0.00,0.00,0.4055884,,,,,,,,,,,4865,15.000,120.000,22.3,14.9992170,6.693,16.5651093,999.023,16.6157646,6.986,,,0.290132,3.917929,0.7,34.68,2.28692e-2,0.00,0.00,-2.0626390,-4.132275,,,,,,,,0.3712750,,1.0,14.9992,62.5,,,,120.0000,120.0000,-5.0000,0.00,0,0,2.5000,,,,0,0.00,0,0.00,19.02,23.53,,,,,,,,
,30366359.92,4865,15.0004,120.000,90.0143967,,,,,,,,,0.0000,-0.0098,0,0.00,0.00,0.00,0.00,0.4055884,,,,,,,,,,,4865,15.000,120.000,22.3,15.0003901,6.693,16.5655136,999.023,16.6505985,6.986,,,0.287106,3.917929,0.7,33.46,2.20639e-2,0.00,0.00,-4.1252780,-3.355717,,,,,,,,0.3663898,,1.0,15.0004,62.5,,,,120.0000,120.0000,-5.0000,0.00,0,0,2.5000,,,,0,0.00,0,0.00,19.71,23.53,,,,,,,,